<?xml version='1.0'?>
<sdf version='1.4'>
  <model name="rodi">
    <static>false</static>
    <link name='base_link'>
      <pose>0 0 0 0 0 0</pose>
      <inertial>
        <mass>0.0200</mass>
        <inertia>
          <!-- m / 12 * (w * w + h * h) -->
          <ixx>1.4506666666666668e-05</ixx>
          <ixy>0</ixy>
          <ixz>0</ixz>
          <!-- m / 12 * (l * l + h * h) -->
          <iyy>2.050666666666667e-05</iyy>
          <iyz>0</iyz>
          <!-- m / 12 * (w * w + l * l) -->
          <izz>2.7333333333333338e-05</izz>
        </inertia>
      </inertial>
      <collision name='base_link_collision'>
        <pose frame=''>0 0 0.0045 0 0 0</pose>
        <geometry>
          <box>
            <size>0.1 0.08 .048</size>
          </box>
        </geometry>
        <surface>
          <friction>
            <ode>
              <mu>1</mu>
              <mu2>1</mu2>
              <fdir1>0 0 0</fdir1>
              <slip1>0</slip1>
              <slip2>0</slip2>
            </ode>
          </friction>
        </surface>
      </collision>

      <visual name='base_link_visual'>
        <pose>0.3 -0.93 -0.0195 0 0 1.57079632679</pose>
        <geometry>
          <mesh>
            <scale>0.001 0.001 0.001</scale>
            <uri>model://rodi/meshes/rodi_base.stl</uri>
          </mesh>
        </geometry>
      </visual>
      <sensor name="sonar" type="sonar">
        <pose>0.04 0 0 0 -1.7 0</pose>
        <sonar>
          <min>0.2</min>
          <max>1.0</max>
          <!-- FIXME: this is an estimated value -->
          <radius>0.5</radius>
        </sonar>
        <always_on>1</always_on>
        <update_rate>30</update_rate>
        <visualize>false</visualize>
      </sensor>
    </link>

    <joint type="fixed" name="ball_caster_joint">
      <parent>base_link</parent>
      <child>ball_caster_link</child>
      <axis>
        <xyz>0 0 1</xyz>
      </axis>
    </joint>

    <link name="ball_caster_link">
      <pose>0.038 0 -0.02 0 0 0</pose>
      <inertial>
        <mass>0.0184</mass>
        <inertia>
          <!-- 2 * m * r * r / 5 -->
          <ixx>1.6693515000000002e-07</ixx>
          <ixy>0</ixy>
          <ixz>0</ixz>
          <iyy>1.6693515000000002e-07</iyy>
          <iyz>0</iyz>
          <izz>1.6693515000000002e-07</izz>
        </inertia>
      </inertial>
      <collision name='ball_caster_collision'>
        <geometry>
          <sphere>
            <radius>.0047625</radius>
          </sphere>
        </geometry>
        <surface>
          <friction>
            <ode>
              <mu>1</mu>
              <mu2>1</mu2>
              <fdir1>0 0 0</fdir1>
              <slip1>0</slip1>
              <slip2>0</slip2>
            </ode>
          </friction>
        </surface>
      </collision>

      <visual name='ball_caster_visual'>
        <geometry>
          <sphere>
            <radius>.0047625</radius>
          </sphere>
        </geometry>
      </visual>
    </link>

    <link name="left_wheel">
      <pose>-0.035 0.045 -0.01 0 1.5707 1.5707</pose>
      <inertial>
        <mass>0.3795</mass>
        <inertia>
	  <!-- m / 12 * (3 * r * r + l * l) -->
          <ixx>3.8234624999999996e-05</ixx>
          <ixy>0</ixy>
          <ixz>0</ixz>
	  <!-- m / 12 * (3 * r * r + l * l) -->
          <iyy>3.8234624999999996e-05</iyy>
          <iyz>0</iyz>
	  <!-- m * r * r / 2 -->
          <izz>7.59e-05</izz>
        </inertia>
      </inertial>
      <collision name="collision">
        <geometry>
          <cylinder>
            <radius>.02</radius>
            <length>.003</length>
          </cylinder>
        </geometry>
        <surface>
          <friction>
            <ode>
              <mu>1</mu>
              <mu2>1</mu2>
              <fdir1>0 0 0</fdir1>
              <slip1>0</slip1>
              <slip2>0</slip2>
            </ode>
          </friction>
        </surface>
      </collision>

      <visual name="visual">
        <geometry>
          <cylinder>
            <radius>.02</radius>
            <length>.003</length>
          </cylinder>
        </geometry>
      </visual>
    </link>

    <link name="right_wheel">
      <pose>-0.035 -0.045 -0.01 0 1.5707 1.5707</pose>
      <inertial>
        <mass>0.3795</mass>
        <inertia>
	  <!-- m / 12 * (3 * r * r + l * l) -->
          <ixx>3.8234624999999996e-05</ixx>
          <ixy>0</ixy>
          <ixz>0</ixz>
	  <!-- m / 12 * (3 * r * r + l * l) -->
          <iyy>3.8234624999999996e-05</iyy>
          <iyz>0</iyz>
	  <!-- m * r * r / 2 -->
          <izz>7.59e-05</izz>
        </inertia>
      </inertial>
      <collision name="collision">
        <geometry>
          <cylinder>
            <radius>.02</radius>
            <length>.003</length>
          </cylinder>
        </geometry>
        <surface>
          <friction>
            <ode>
              <mu>1</mu>
              <mu2>1</mu2>
              <fdir1>0 0 0</fdir1>
              <slip1>0</slip1>
              <slip2>0</slip2>
            </ode>
          </friction>
        </surface>
      </collision>
      <visual name="visual">
        <geometry>
          <cylinder>
            <radius>.02</radius>
            <length>.003</length>
          </cylinder>
        </geometry>
      </visual>
    </link>

    <joint type="revolute" name="left_wheel_servo">
      <parent>base_link</parent>
      <child>left_wheel</child>
      <axis>
        <xyz>0 1 0</xyz>
      </axis>
    </joint>

    <joint type="revolute" name="right_wheel_servo">
      <parent>base_link</parent>
      <child>right_wheel</child>
      <axis>
        <xyz>0 1 0</xyz>
      </axis>
    </joint>

  </model>
</sdf>
